# 异常处理

在 Node.js 中，如果存在未捕获的异常，那么就会导致程序退出。

```js
const invalidJSON = "{name: 'Front-End Wizard', age: 25;}";
JSON.parse(invalidJSON);
console.log("后续代码...");
```

在上面的代码中，JSON.parse 进行解析的时候会产生异常，抛出 SytaxError 的错误，程序也就终止了，后面的代码不会再被执行。

对于基于 Node.js 的 Electron 来讲，也同样存在这样不稳定的因素。

因此，在编写代码的过程红，对异常的处理就非常重要。

常见的异常处理分为两大类：

- 局部异常处理
- 全局异常处理



## 局部异常处理

所谓局部异常处理，指的就是开发人员在编写代码的过程中，意识到某一处可能会产生异常，于是有意识的捕获和处理异常。

```js
const invalidJSON = "{name: 'Front-End Wizard', age: 25;}";
try {
  JSON.parse(invalidJSON);
} catch (e) {
  console.error("解析 JSON 时发生错误：", e.message);
}
console.log("后续代码...");
```

在上面的代码中，我们使用 try 包括 JSON.parse 这一段解析逻辑，当产生异常的时候，会进入到 catch，catch 里面会对异常进行处理，这样子的话即便产生了异常，程序也能够继续往后面执行，不会被中断。

常见需要捕获异常的地方：

- 数据库连接
- 网络请求
- ...

不过，局部异常处理，会存在两个问题：

1. 和业务逻辑有很大的相关性
2. 非常依赖于开发人员的代码质量意识

在真实项目，往往会遇到很多本来应该去捕获异常的地方，忘记去捕获了，因此在这种时候，我们就需要第二种异常处理机制：全局异常处理。



## 全局异常处理

无论是 Node.js 环境还是 Chromium 环境，都提供了相应的全局事件，我们可以通过这些事件来捕获异常。

- Node.js 环境：对应的事件注册对象为 process
  - 事件名：uncaughtException
  - 事件名：unhandledRejection
- Chromium 环境：对应的事件注册对象为 window
  - 事件名：error
  - 事件名：unhandledRejection

因此，我们可以在我们的项目中，单独书写一个模块，进行全局的异常捕获。

```js
let isInited = false; // 检查是否已经初始化

function initErrorHandler() {
  if (isInited) return;
  if (!isInited) {
    // 进行初始化操作
    isInited = true;
    if (process.type === "renderer") {
      // 进入此分支，说明是来自渲染进程的错误
      window.addEventListener("error", (e) => {
        e.preventDefault();
        console.log("这是来自于渲染进程的 error 类型的异常");
        console.log(e.error);
      });
      window.addEventListener("unhandledRejection", (e) => {
        e.preventDefault();
        console.log("这是来自于渲染进程的 unhandledRejection 类型的异常");
        console.log(e.reason);
      });
    } else {
      // 进入此分支，说明是来自主进程的错误
      process.on("uncaughtException", (error) => {
        console.log("这是来自于主进程的 uncaughtException 类型的异常");
        console.log(error);
      });
      process.on("unhandledRejection", (error) => {
        console.log("这是来自于主进程的 unhandledRejection 类型的异常");
        console.log(error);
      });
    }
  }
}

module.exports = initErrorHandler;
```



## 关于同步异常和异步异常

在上面，虽然我们添加了全局的异常捕获处理模块，但是这是针对异步的全局错误进行的捕获，例如：

- 正常该捕获但是忘了捕获的异常
- 未处理的 promise 拒绝

也就是说，这里的全局异常捕获模块，是作为 **<u>最后一道防线</u>**。

一般来讲，针对同步的异常，例如上面的 JSON.parse 这一类的异常，仍然是应该通过 try ... catch 去捕获的，除非开发人员实在是忘了进行同步捕获，那么我们就在全局异常捕获模块（最后一道防线）将其捕获到。

```js
const initErrorHandler = require("../errorHandler");
initErrorHandler();

const btn = document.getElementById("btn");
btn.addEventListener("click", () => {
  //   throw new Error("渲染进程主动抛出错误");
  //   new promise((resolve, reject) => {
  //     reject("手动抛出一个错误");
  //   });
  const invalidJSON = "{name: 'Front-End Wizard', age: 25;}";
  try {
    JSON.parse(invalidJSON);
  } catch (e) {
    console.error("解析 JSON 时发生错误：", e.message);
  }
  console.log("后续代码...");
});
```



最后，我们可以对我们的全局异常处理模块再次进行封装，使其同时支持捕获同步异常和异步异常，以及全局异常处理模块：

```js
let isInited = false; // 检查是否已经初始化
module.exports = {
  // 初始化全局异常处理模块
  initGlobalErrorHandler: function () {
    if (isInited) return;
    if (!isInited) {
      // 进行初始化操作
      isInited = true;
      if (process.type === "renderer") {
        // 进入此分支，说明是来自渲染进程的错误
        window.addEventListener("error", (e) => {
          e.preventDefault();
          console.log("这是来自于渲染进程的 error 类型的异常");
          console.log(e.error);
        });
        window.addEventListener("unhandledRejection", (e) => {
          e.preventDefault();
          console.log("这是来自于渲染进程的 unhandledRejection 类型的异常");
          console.log(e.reason);
        });
      } else {
        // 进入此分支，说明是来自主进程的错误
        process.on("uncaughtException", (error) => {
          console.log("这是来自于主进程的 uncaughtException 类型的异常");
          console.log(error);
        });
        process.on("unhandledRejection", (error) => {
          console.log("这是来自于主进程的 unhandledRejection 类型的异常");
          console.log(error);
        });
      }
    }
  },
  // 用于捕获同步代码的异常
  captureSyncErrors: function (func) {
    try {
      func();
    } catch (error) {
      console.error("捕获到同步代码的异常：", error);
      // 这里往往会添加后续的逻辑，比如将错误信息发送到服务器，记录到错误日志中等
    }
  },
  // 用于捕获异步代码的异常
  captureAsyncErrors: async function (asyncFunc) {
    try {
      await asyncFunc();
    } catch (error) {
      console.error("捕获到异步代码的异常：", error);
      // 这里往往会添加后续的逻辑，比如将错误信息发送到服务器，记录到错误日志中等
    }
  },
};

```

